<robot name="single_joint_example">

    <link name="base_link">
        <inertial>
            <mass value="100" />
            <inertia ixx="100" ixy="0" ixz="0" iyy="100" iyz="0" izz="100" />
        </inertial>
        <visual>
            <geometry>
                <box size="1 1 1" />
            </geometry>
        </visual>
        <collision>
            <geometry>
                <box size="1 1 1" />
            </geometry>
        </collision>
    </link>

    <joint name="axis" type="continuous">
        <origin xyz="0 0 0.55" rpy="0 0 0" />
        <parent link="base_link" />
        <child link="child_link" />
        <axis xyz="0 0 1" />
    </joint>

    <transmission name="trans">
        <type>transmission_interface/SimpleTransmission</type>
        <joint name="axis">
            <hardwareInterface>hardware_interface/PosVelJointInterface</hardwareInterface>
            <hardwareInterface>hardware_interface/PositionJointInterface</hardwareInterface>
            <hardwareInterface>hardware_interface/VelocityJointInterface</hardwareInterface>
            <hardwareInterface>hardware_interface/EffortJointInterface</hardwareInterface>
        </joint>
        <actuator name="motor">
            <mechanicalReduction>1</mechanicalReduction>
        </actuator>
    </transmission>

    <link name="child_link">
        <inertial>
            <mass value="1" />
            <inertia ixx="1" ixy="0" ixz="0" iyy="1" iyz="0" izz="1" />
        </inertial>
        <visual>
            <geometry>
                <box size="1 1 0.1" />
            </geometry>
        </visual>
        <collision>
            <geometry>
                <box size="1 1 0.1" />
            </geometry>
        </collision>
    </link>

    <gazebo>
        <plugin filename="libGazeboLayeredHardware.so" name="layered_hardware" />
    </gazebo>

</robot>